Workbook

Sheet Panel
B1: Panel · Sistema de Gestión MP 2026
B2: Pulso del equipamiento clínico — HHHA · se actualiza al abrir en Excel
B3: Hoy: | C3: =TODAY() -> 46191
B5: OPERATIVIDAD (hoy)
B6: Casos abiertos | C6: Equipos No Operativos | D6: En servicio técnico | E6: Dados de baja | F6: Pend. documentales
B7: =COUNTIF('1. Órdenes de Trabajo'!$J$2:$J$301,"Abierto") -> 11 | C7: =COUNTIFS('1. Órdenes de Trabajo'!$J$2:$J$301,"Abierto",'1. Órdenes de Trabajo'!$H$2:$H$301,"No Operativo") -> 11 | D7: =SUMPRODUCT(('5. Servicio Técnico (Envíos)'!$A$2:$A$301<>"")*('5. Servicio Técnico (Envíos)'!$K$2:$K$301<>"Operativo")) -> 8 | E7: =COUNTIF('6. Bajas'!$A$2:$A$301,"?*") -> 0 | F7: =COUNTIF('4. Visitas Técnicas'!$L$2:$L$301,"No")+COUNTIF('5. Servicio Técnico (Envíos)'!$M$2:$M$301,"No") -> 2
B9: PROGRAMA PREVENTIVO 2026
B10: MP programadas | C10: MP ejecutadas | D10: % avance | E10: Reprogramadas | F10: Por correctivo
B11: =SUM('MP Carta 2026'!$U$4:$U$969) -> 1234 | C11: =SUM('MP Carta 2026'!$V$4:$V$969) -> 888 | D11: =IFERROR(SUM('MP Carta 2026'!$V$4:$V$969)/SUM('MP Carta 2026'!$U$4:$U$969),"") -> 0.71961102 | E11: =SUMPRODUCT(--('MP Carta 2026'!$I$4:$T$969="R")) -> 299 | F11: =SUM('MP Carta 2026'!$X$4:$X$969) -> 47
B13: PENDIENTES (cola de acción)
B14: Por hacer | C14: Vencidos | D14: Completados
B15: =COUNTIF(Pendientes!$H$2:$H$200,"Por hacer") -> 54 | C15: =COUNTIFS(Pendientes!$H$2:$H$200,"Por hacer",Pendientes!$G$2:$G$200,"Vencido") -> 24 | D15: =COUNTIF(Pendientes!$H$2:$H$200,"Completado") -> 5
B17: EQUIPOS CRÍTICOS — en correctivo + preventivo + pendientes
B18: N° Inventario | C18: Equipo | D18: Servicio | E18: Caso abierto | F18: Pend. por hacer
B19: 2-013590 | C19: =IFERROR(VLOOKUP($B19,Equipos!$C$2:$D$967,2,FALSE()),"") -> Ventilador Mecánico | D19: =IFERROR(VLOOKUP($B19,Equipos!$C$2:$F$967,3,FALSE()),"") -> UPC Adulto | E19: =IF(COUNTIFS('1. Órdenes de Trabajo'!$F$2:$F$301,$B19,'1. Órdenes de Trabajo'!$J$2:$J$301,"Abierto")>0,"Sí","No") -> Sí | F19: =COUNTIFS(Pendientes!$C$2:$C$200,$B19,Pendientes!$H$2:$H$200,"Por hacer") -> 4
B20: 2-110571 | C20: =IFERROR(VLOOKUP($B20,Equipos!$C$2:$D$967,2,FALSE()),"") -> Ventilador Mecánico | D20: =IFERROR(VLOOKUP($B20,Equipos!$C$2:$F$967,3,FALSE()),"") -> UPC Adulto | E20: =IF(COUNTIFS('1. Órdenes de Trabajo'!$F$2:$F$301,$B20,'1. Órdenes de Trabajo'!$J$2:$J$301,"Abierto")>0,"Sí","No") -> No | F20: =COUNTIFS(Pendientes!$C$2:$C$200,$B20,Pendientes!$H$2:$H$200,"Por hacer") -> 3
B21: 2-119890 | C21: =IFERROR(VLOOKUP($B21,Equipos!$C$2:$D$967,2,FALSE()),"") -> Ventilador Mecánico | D21: =IFERROR(VLOOKUP($B21,Equipos!$C$2:$F$967,3,FALSE()),"") -> UPC 3er Piso | E21: =IF(COUNTIFS('1. Órdenes de Trabajo'!$F$2:$F$301,$B21,'1. Órdenes de Trabajo'!$J$2:$J$301,"Abierto")>0,"Sí","No") -> Sí | F21: =COUNTIFS(Pendientes!$C$2:$C$200,$B21,Pendientes!$H$2:$H$200,"Por hacer") -> 1
B22: 2-119891 | C22: =IFERROR(VLOOKUP($B22,Equipos!$C$2:$D$967,2,FALSE()),"") -> Ventilador Mecánico | D22: =IFERROR(VLOOKUP($B22,Equipos!$C$2:$F$967,3,FALSE()),"") -> UPC 3er Piso | E22: =IF(COUNTIFS('1. Órdenes de Trabajo'!$F$2:$F$301,$B22,'1. Órdenes de Trabajo'!$J$2:$J$301,"Abierto")>0,"Sí","No") -> Sí | F22: =COUNTIFS(Pendientes!$C$2:$C$200,$B22,Pendientes!$H$2:$H$200,"Por hacer") -> 1
B23: 2-121203 | C23: =IFERROR(VLOOKUP($B23,Equipos!$C$2:$D$967,2,FALSE()),"") -> Ventilador Mecánico | D23: =IFERROR(VLOOKUP($B23,Equipos!$C$2:$F$967,3,FALSE()),"") -> UPC 3er Piso | E23: =IF(COUNTIFS('1. Órdenes de Trabajo'!$F$2:$F$301,$B23,'1. Órdenes de Trabajo'!$J$2:$J$301,"Abierto")>0,"Sí","No") -> Sí | F23: =COUNTIFS(Pendientes!$C$2:$C$200,$B23,Pendientes!$H$2:$H$200,"Por hacer") -> 2
B26: IR A:
B27: =HYPERLINK("#Pendientes!A1","▸ Pendientes (qué hacer hoy)") -> ▸ Pendientes (qué hacer hoy)
B28: =HYPERLINK("#'Ficha de Equipo'!A1","▸ Ficha de Equipo (estado 360)") -> ▸ Ficha de Equipo (estado 360)
B29: =HYPERLINK("#Tablero!A1","▸ Tablero correctivo") -> ▸ Tablero correctivo
B30: =HYPERLINK("#'MP Carta 2026'!A1","▸ MP Carta 2026") -> ▸ MP Carta 2026

Sheet Pendientes
A1: Equipo | B1: Serie | C1: N° Inventario | D1: Tipo de pendiente | E1: Fecha compromiso | F1: Días de atraso | G1: Situación | H1: Estado | I1: Prioridad | J1: Responsable Ejecutivo | K1: Responsable Administrativo | L1: En espera de | M1: Descripción | N1: Tareas | O1: Fecha completado | P1: Creado
A2: Máquina Diálisis | B2: 8VCAJN39 | C2: 2-113999 | D2: Reprogramación Mantención Preventiva | E2: 15-06-2026 | F2: 2 | G2: Vencido | H2: Por hacer | I2: Media | J2: Cristián Beltrán Oviedo | K2: Cristián Beltrán Oviedo | M2: Reprogramación de MP por causal C6 (MP del 30-04-2026). | N2: [ ] Sacar la firma del reporte de reprogramación (causal C6) | O2: — | P2: 12-06-2026
A3: Máquina Diálisis | B3: 3SXA4HCP | C3: 2-128062 | D3: Otro | E3: 12-06-2026 | G3: Completado | H3: Completado | I3: Media | J3: Cristián Beltrán Oviedo | K3: Cristián Beltrán Oviedo | M3: No se encuentra la carpeta. | O3: 15-06-2026 | P3: 12-06-2026
A4: Máquina Diálisis | B4: 3SXA4HDJ | C4: 2-128045 | D4: Protocolo Interno de Mantenimiento | E4: 12-06-2026 | F4: 5 | G4: Vencido | H4: Por hacer | I4: Media | J4: Cristián Beltrán Oviedo | K4: Cristián Beltrán Oviedo | M4: Falta el protocolo interno de MP de esta máquina de diálisis. | N4: [ ] Conseguir/completar el protocolo interno de MP | O4: — | P4: 12-06-2026
A5: Máquina Diálisis | B5: 0VSANY78 | C5: 2-130653 | D5: Protocolo Interno de Mantenimiento | E5: 12-06-2026 | F5: 5 | G5: Vencido | H5: Por hacer | I5: Media | J5: Cristián Beltrán Oviedo | K5: Cristián Beltrán Oviedo | M5: Falta el protocolo interno de MP de esta máquina de diálisis. | N5: [ ] Conseguir/completar el protocolo interno de MP | O5: — | P5: 12-06-2026
A6: Máquina Diálisis | B6: 0VSANY78 | C6: 2-130653 | D6: Protocolo Externo de Mantenimiento | E6: 12-06-2026 | F6: 5 | G6: Vencido | H6: Por hacer | I6: Media | J6: Cristián Beltrán Oviedo | K6: Cristián Beltrán Oviedo | M6: Falta el protocolo externo de MP de esta máquina de diálisis. | N6: [ ] Conseguir/completar el protocolo externo de MP | O6: — | P6: 12-06-2026
A7: Ventilador Mecánico | B7: ASFN-0008 | C7: 2-013590 | D7: Otro | E7: 15-06-2026 | F7: 2 | G7: Vencido | H7: Por hacer | I7: Media | J7: Ricardo Matus Aroca | K7: Cristián Beltrán Oviedo | M7: Falta el reporte de reparación (folio 19-6709). | N7: [ ] Conseguir el reporte de reparación (folio 19-6709) y archivarlo | O7: — | P7: 12-06-2026
A8: Ventilador Mecánico | B8: ASFN-0008 | C8: 2-013590 | D8: Reprogramación Mantención Preventiva | E8: 30-04-2026 | F8: 48 | G8: Vencido | H8: Por hacer | I8: Media | J8: Ricardo Matus Aroca | K8: Cristián Beltrán Oviedo | M8: Reprogramación de MP por causal C3 (MP del 30-04-2026). | N8: [ ] Generar el reporte de reprogramación (causal C3 · 30-04-2026) [ ] Imprimir el reporte de reprogramación [ ] Firma del supervisor del servicio clínico [ ] Firma del jefe de equipos médicos | O8: — | P8: 12-06-2026
A9: Monitor Multiparámetros | B9: 5494254562 | C9: 2-007495 | D9: Reprogramación Mantención Preventiva | E9: 12-06-2026 | F9: 5 | G9: Vencido | H9: Por hacer | I9: Media | J9: Ignacio Berner Bergara | K9: Cristián Beltrán Oviedo | M9: Reprogramación de MP por causal C5 (MP del 30-04-2026). | N9: [ ] Generar el reporte de reprogramación (causal C5 · 30-04-2026) [ ] Imprimir el reporte de reprogramación [ ] Firma del supervisor del servicio clínico [ ] Firma del jefe de equipos médicos | O9: — | P9: 12-06-2026
A10: Máquina de Anestesia | B10: ASMB-0231 | C10: 2-117816 | D10: Otro | E10: 12-06-2026 | F10: 5 | G10: Vencido | H10: Por hacer | I10: Media | J10: Cristián Beltrán Oviedo | K10: Cristián Beltrán Oviedo | M10: Falta el protocolo interno de MP y hay una causal nueva por revisar. | N10: [ ] Armar/conseguir el protocolo interno de MP [ ] Revisar la causal nueva [ ] Consultar con Marco | O10: — | P10: 12-06-2026
A11: Monitor Multiparámetros | B11: 5494252457 | C11: 2-016863 | D11: Reprogramación Mantención Preventiva | E11: 12-06-2026 | F11: 5 | G11: Vencido | H11: Por hacer | I11: Media | J11: Ignacio Berner Bergara | K11: Cristián Beltrán Oviedo | M11: Reprogramación de MP por causal C5 (MP del 30-04-2026). | N11: [ ] Generar el reporte de reprogramación (causal C5 · 30-04-2026) [ ] Imprimir el reporte de reprogramación [ ] Firma del supervisor del servicio clínico [ ] Firma del jefe de equipos médicos | O11: — | P11: 12-06-2026
A12: Ventilador Mecánico | B12: 40966N0126 | C12: 2-119887 | D12: Protocolo Interno de Mantenimiento | E12: 15-06-2026 | F12: 2 | G12: Vencido | H12: Por hacer | I12: Media | J12: Ricardo Matus Aroca | K12: Cristián Beltrán Oviedo | M12: MP del 09-04-2026 (resultado Sí). Falta el reporte de MP; enviarlo a Ignacio Díaz (Medtronic) para que lo complete. | N12: [ ] Enviar el reporte de MP a Ignacio Díaz (Medtronic) para que lo complete [ ] Firma de los profesionales del servicio clínico [ ] Firma de Marco [ ] Firma de Don Ricardo [ ] Archivar el documento | O12: — | P12: 12-06-2026
A13: Máquina Diálisis | B13: 3SXA4HCP | C13: 2-128062 | D13: Reprogramación Mantención Preventiva | E13: 15-06-2026 | F13: 2 | G13: Vencido | H13: Por hacer | I13: Media | J13: Cristián Beltrán Oviedo | K13: Cristián Beltrán Oviedo | M13: Reprogramación de MP por causal C6 (MP del 30-04-2026). | N13: [ ] Generar el reporte de reprogramación (causal C6 · 30-04-2026) [ ] Imprimir el reporte de reprogramación [ ] Firma del supervisor del servicio clínico [ ] Firma del jefe de equipos médicos | O13: — | P13: 15-06-2026
A14: Ventilador Mecánico | B14: 40966N0134 | C14: 2-119890 | D14: Protocolo Interno de Mantenimiento | E14: 18-06-2026 | G14: Vigente | H14: Por hacer | I14: Media | J14: Personal Externo | K14: Cristián Beltrán Oviedo | M14: Solicitar a Ignacio Díaz (Medtronic) que envíe el protocolo de mantención preventiva firmado. | N14: [ ] Enviar el reporte de MP a Medtronic para que lo complete [ ] Sacar la firma de los profesionales del servicio [ ] Sacar la firma de Marco [ ] Sacar la firma de Don Ricardo [ ] Archivar el documento | O14: — | P14: 15-06-2026
A15: Ventilador Mecánico | B15: 40966N0118 | C15: 2-119891 | D15: Protocolo Interno de Mantenimiento | E15: 18-06-2026 | G15: Vigente | H15: Por hacer | I15: Media | J15: Personal Externo | K15: Cristián Beltrán Oviedo | M15: Falta el protocolo de mantención preventiva interno de Medtronic. | N15: [ ] Enviar a Ignacio Díaz (Medtronic) el protocolo para que lo complete [ ] Sacar la firma de Marco [ ] Sacar la firma de Ricardo Matus [ ] Firma del servicio clínico [ ] Archivar el documento | O15: — | P15: 15-06-2026
A16: Ventilador Mecánico | B16: ASCL-0116 | C16: 2-003526 | D16: Protocolo Interno de Mantenimiento | E16: 18-06-2026 | G16: Completado | H16: Completado | I16: Media | J16: Personal Externo | K16: Cristián Beltrán Oviedo | M16: Generado por la MP del 18-05-2026 (resultado Sí): falta el protocolo de MP interno. | N16: [Sí] Conseguir el reporte de MP interno y archivarlo | O16: 17-06-2026 | P16: 15-06-2026
A17: Ventilador Mecánico | B17: ASJL-0081 | C17: 2-121203 | D17: Otro | E17: 15-06-2026 | F17: 2 | G17: Vencido | H17: Por hacer | I17: Media | J17: Cristián Beltrán Oviedo | K17: Cristián Beltrán Oviedo | M17: Actualizar en la carta Gantt el estado de la ST (solicitud de trabajo). | N17: [ ] Actualizar en la carta Gantt el estado de la ST | O17: — | P17: 15-06-2026
A18: Ventilador Mecánico | B18: TV01802190B | C18: 2-116500 | D18: Otro | E18: 15-06-2026 | F18: 2 | G18: Vencido | H18: Por hacer | I18: Media | J18: Cristián Beltrán Oviedo | K18: Cristián Beltrán Oviedo | M18: El equipo regresó el 15-06-2026. Se había enviado el año pasado por falla; Don Ricardo recuerda que el envío fue por garantía, pero Andover quedó esperando una orden de compra pese a tratarse de garantía. | N18: [ ] Aclarar con Andover si corresponde garantía u orden de compra [ ] Regularizar el ingreso del equipo | O18: — | P18: 15-06-2026
A19: Ventilador Mecánico | B19: ASFM-0082 | C19: 2-013598 | D19: Otro | E19: 22-06-2026 | G19: Vigente | H19: Por hacer | I19: Media | J19: Cristián Beltrán Oviedo | K19: Cristián Beltrán Oviedo | M19: Generada automáticamente por la MP del 18-05-2026 (resultado Sí). Falta especificar qué acción queda pendiente. | N19: [ ] Definir/revisar qué falta de esta MP | O19: — | P19: 15-06-2026
A20: Ventilador Mecánico | B20: ASHK-0152 | C20: 2-110569 | D20: Otro | E20: 22-06-2026 | G20: Vigente | H20: Por hacer | I20: Media | J20: Cristián Beltrán Oviedo | K20: Cristián Beltrán Oviedo | M20: Generada automáticamente por la MP del 18-05-2026 (resultado Sí). Falta especificar qué acción queda pendiente. | N20: [ ] Definir/revisar qué falta de esta MP | O20: — | P20: 15-06-2026
A21: Ventilador Mecánico | B21: ASHK-0155 | C21: 2-110568 | D21: Protocolo Interno de Mantenimiento | E21: 18-06-2026 | G21: Vigente | H21: Por hacer | I21: Media | J21: Personal Externo | K21: Cristián Beltrán Oviedo | M21: Generado por la MP del 20-05-2026 (resultado Sí): falta el reporte de MP interno (lo tiene Luis Hurtado). | N21: [ ] Solicitar a Luis Hurtado el reporte de MP interno y archivarlo | O21: — | P21: 15-06-2026
A22: Ventilador Mecánico | B22: ASHK-0157 | C22: 2-110566 | D22: Protocolo Interno de Mantenimiento | E22: 22-06-2026 | G22: Vigente | H22: Por hacer | I22: Media | J22: Personal Externo | K22: Cristián Beltrán Oviedo | M22: Generado por la MP del 14-05-2026 (resultado Sí): falta el reporte de MP interno (lo tiene Luis Hurtado). | N22: [ ] Solicitar a Luis Hurtado el reporte de MP interno y archivarlo | O22: — | P22: 15-06-2026
A23: Ventilador Mecánico | B23: ASHK-0158 | C23: 2-110574 | D23: Protocolo Interno de Mantenimiento | E23: 22-06-2026 | G23: Vigente | H23: Por hacer | I23: Media | J23: Personal Externo | K23: Cristián Beltrán Oviedo | M23: Generado por la MP del 06-05-2026 (resultado Sí): falta el reporte de MP interno (lo tiene Luis Hurtado). | N23: [ ] Solicitar a Luis Hurtado el reporte de MP interno y archivarlo | O23: — | P23: 15-06-2026
A24: Ventilador Mecánico | B24: ASHK-0162 | C24: 2-110575 | D24: Protocolo Interno de Mantenimiento | E24: 18-06-2026 | G24: Vigente | H24: Por hacer | I24: Media | J24: Personal Externo | K24: Cristián Beltrán Oviedo | M24: Generado por la MP del 13-05-2026 (resultado Sí): falta el reporte de MP interno (lo tiene Luis Hurtado). | N24: [ ] Solicitar a Luis Hurtado el reporte de MP interno y archivarlo | O24: — | P24: 15-06-2026
A25: Ventilador Mecánico | B25: ASHK-0163 | C25: 2-110572 | D25: Protocolo Interno de Mantenimiento | E25: 18-06-2026 | G25: Vigente | H25: Por hacer | I25: Media | J25: Personal Externo | K25: Cristián Beltrán Oviedo | M25: Generado por la MP del 13-05-2026 (resultado Sí): falta el reporte de MP interno (lo tiene Luis Hurtado). | N25: [ ] Solicitar a Luis Hurtado el reporte de MP interno y archivarlo | O25: — | P25: 15-06-2026
A26: Ventilador Mecánico | B26: ASJA-0096 | C26: 2-116308 | D26: Protocolo Interno de Mantenimiento | E26: 18-06-2026 | G26: Vigente | H26: Por hacer | I26: Media | J26: Personal Externo | K26: Cristián Beltrán Oviedo | M26: Generado por la MP del 18-05-2026 (resultado Sí): falta el reporte de MP interno (lo tiene Luis Hurtado). | N26: [ ] Solicitar a Luis Hurtado el reporte de MP interno y archivarlo | O26: — | P26: 15-06-2026
A27: Ventilador Mecánico | B27: ASJA-0097 | C27: 2-116302 | D27: Protocolo Interno de Mantenimiento | E27: 18-06-2026 | G27: Vigente | H27: Por hacer | I27: Media | J27: Personal Externo | K27: Cristián Beltrán Oviedo | M27: Generado por la MP del 14-05-2026 (resultado Sí): falta el reporte de MP interno (lo tiene Luis Hurtado). | N27: [ ] Solicitar a Luis Hurtado el reporte de MP interno y archivarlo | O27: — | P27: 15-06-2026
A28: Ventilador Mecánico | B28: ASJA-0098 | C28: 2-116303 | D28: Protocolo Interno de Mantenimiento | E28: 18-06-2026 | G28: Vigente | H28: Por hacer | I28: Media | J28: Personal Externo | K28: Cristián Beltrán Oviedo | M28: Generado por la MP del 07-05-2026 (resultado Sí): falta el reporte de MP interno (lo tiene Luis Hurtado). | N28: [ ] Solicitar a Luis Hurtado el reporte de MP interno y archivarlo | O28: — | P28: 15-06-2026
A29: Ventilador Mecánico | B29: ASJA-0138 | C29: 2-116301 | D29: Protocolo Interno de Mantenimiento | E29: 22-06-2026 | G29: Vigente | H29: Por hacer | I29: Media | J29: Personal Externo | K29: Cristián Beltrán Oviedo | M29: Generado por la MP del 20-05-2026 (resultado Sí): falta el reporte de MP interno (lo tiene Luis Hurtado). | N29: [ ] Solicitar a Luis Hurtado el reporte de MP interno y archivarlo | O29: — | P29: 15-06-2026
A30: Ventilador Mecánico | B30: ASJF-0008 | C30: 2-116305 | D30: Protocolo Interno de Mantenimiento | E30: 18-06-2026 | G30: Vigente | H30: Por hacer | I30: Media | J30: Personal Externo | K30: Cristián Beltrán Oviedo | M30: Generado por la MP del 14-05-2026 (resultado Sí): falta el reporte de MP interno (lo tiene Luis Hurtado). | N30: [ ] Solicitar a Luis Hurtado el reporte de MP interno y archivarlo | O30: — | P30: 15-06-2026
... A45: Ventilador Mecánico | B45: ASHK-0158 | C45: 2-110574 | D45: Reprogramación Mantención Preventiva | E45: 18-06-2026 | G45: Vigente | H45: Por hacer | I45: Media | J45: Personal Externo | K45: Cristián Beltrán Oviedo | M45: Reprogramación de MP por causal C6 (MP del 30-04-2026). | N45: [ ] Imprimir el reporte de reprogramación (causal C6) | O45: — | P45: 15-06-2026
A46: Ventilador Mecánico | B46: ASHK-0163 | C46: 2-110572 | D46: Reprogramación Mantención Preventiva | E46: 30-05-2026 | F46: 18 | G46: Vencido | H46: Por hacer | I46: Media | J46: Personal Externo | K46: Cristián Beltrán Oviedo | M46: Reprogramación de MP por causal C6 (MP del 30-04-2026). | N46: [ ] Imprimir el reporte de reprogramación (causal C6) | O46: — | P46: 15-06-2026
A47: Ventilador Mecánico | B47: ASHK-0162 | C47: 2-110575 | D47: Reprogramación Mantención Preventiva | E47: 18-06-2026 | G47: Vigente | H47: Por hacer | I47: Media | J47: Personal Externo | K47: Cristián Beltrán Oviedo | M47: Reprogramación de MP por causal C6 (MP del 30-04-2026). | N47: [ ] Imprimir el reporte de reprogramación (causal C6) | O47: — | P47: 15-06-2026
A48: Ventilador Mecánico | B48: ASHK-0155 | C48: 2-110568 | D48: Reprogramación Mantención Preventiva | E48: 18-06-2026 | G48: Vigente | H48: Por hacer | I48: Media | J48: Personal Externo | K48: Cristián Beltrán Oviedo | M48: Reprogramación de MP por causal C6 (MP del 30-04-2026). | N48: [ ] Imprimir el reporte de reprogramación (causal C6) | O48: — | P48: 15-06-2026
A49: Ventilador Mecánico | B49: ASHK-0157 | C49: 2-110566 | D49: Reprogramación Mantención Preventiva | E49: 18-06-2026 | G49: Completado | H49: Completado | I49: Media | J49: Personal Externo | K49: Cristián Beltrán Oviedo | M49: Reprogramación de MP por causal C6 (MP del 30-04-2026). | N49: [ ] Imprimir el reporte de reprogramación (causal C6) | O49: 17-06-2026 | P49: 15-06-2026
A50: Ventilador Mecánico | B50: ASNH-0098 | C50: 2-120837 | D50: Reprogramación Mantención Preventiva | E50: 30-05-2026 | F50: 18 | G50: Vencido | H50: Por hacer | I50: Media | J50: Personal Externo | K50: Cristián Beltrán Oviedo | M50: Reprogramación de MP (externa) por causal C6 (MP del 30-04-2026). | N50: [No] Protocolo de MP interno (lo tiene Luis Hurtado) [Sí] Protocolo de MP externo [ ] Imprimir el reporte de reprogramación (causal C6) | O50: — | P50: 16-06-2026
A51: Ventilador Mecánico | B51: ASNK-0045 | C51: 2-120945 | D51: Reprogramación Mantención Preventiva | E51: 30-05-2026 | F51: 18 | G51: Vencido | H51: Por hacer | I51: Media | J51: Cristián Beltrán Oviedo | K51: Cristián Beltrán Oviedo | M51: Reprogramación de MP (externa) por causal C6 (MP del 30-04-2026). | N51: [No] Protocolo de MP interno [Sí] Protocolo de MP externo [ ] Generar la reprogramación (causal C6) | O51: — | P51: 16-06-2026
A52: Ventilador Mecánico | B52: ASNM-0002 | C52: 2-120948 | D52: Reprogramación Mantención Preventiva | E52: 30-05-2026 | F52: 18 | G52: Vencido | H52: Por hacer | I52: Media | J52: Cristián Beltrán Oviedo | K52: Cristián Beltrán Oviedo | M52: Reprogramación de MP (externa) por causal C6 (MP del 30-04-2026). | N52: [—] Protocolo de MP interno [—] Protocolo de MP externo [ ] Imprimir el reporte de reprogramación (causal C6) | O52: — | P52: 16-06-2026
A53: Ventilador Mecánico | B53: ASFN-0008 | C53: 2-013590 | D53: Protocolo Interno de Mantenimiento | E53: 12-02-2026 | F53: 125 | G53: Vencido | H53: Por hacer | I53: Media | J53: Personal Externo | K53: Cristián Beltrán Oviedo | M53: Falta el protocolo de MP interno; solicitarlo a Miguel Hernández (Drager). | N53: [ ] Solicitar a Miguel Hernández (Drager) el reporte de MP interno y archivarlo | O53: — | P53: 16-06-2026
A54: Ventilador Mecánico | B54: ASFN-0008 | C54: 2-013590 | D54: Otro | E54: 16-06-2026 | F54: 1 | G54: Vencido | H54: Por hacer | I54: Media | J54: Ricardo Matus Aroca | K54: Cristián Beltrán Oviedo | M54: Falta el informe de reparación del equipo (figura reparado el 05-06-2026). | N54: [ ] Conseguir el informe de reparación y archivarlo | O54: — | P54: 16-06-2026
...

Sheet Ficha de Equipo
B1: Ficha de Equipo
B2: Elige el N° de inventario y verás todo su estado e historial
B4: N° Inventario: | C4: 2-118732
B6: IDENTIDAD
C7: Equipo | D7: Servicio | E7: Ubicación
C8: =IFERROR(VLOOKUP($C$4,Equipos!$C$2:$M$967,2,FALSE()),"—") -> Monitor Multiparámetros | D8: =IFERROR(VLOOKUP($C$4,Equipos!$C$2:$M$967,3,FALSE()),"—") -> Pabellón Quirúrgico | E8: =IFERROR(VLOOKUP($C$4,Equipos!$C$2:$M$967,5,FALSE()),"—") -> Pabellón 7
C9: Marca | D9: Modelo | E9: Serie
C10: =IFERROR(VLOOKUP($C$4,Equipos!$C$2:$M$967,7,FALSE()),"—") -> Drager | D10: =IFERROR(VLOOKUP($C$4,Equipos!$C$2:$M$967,8,FALSE()),"—") -> M540 | E10: =IFERROR(VLOOKUP($C$4,Equipos!$C$2:$M$967,9,FALSE()),"—") -> 5613543568
B12: ESTADO ACTUAL
B13: ¿Caso correctivo abierto? | D13: =IF(COUNTIFS('1. Órdenes de Trabajo'!$F$2:$F$301,$C$4,'1. Órdenes de Trabajo'!$J$2:$J$301,"Abierto")>0,"SÍ — en proceso","No") -> SÍ — en proceso
B14: ¿En servicio técnico? | D14: =IF(SUMPRODUCT(('5. Servicio Técnico (Envíos)'!$C$2:$C$301=$C$4)*('5. Servicio Técnico (Envíos)'!$K$2:$K$301<>"Operativo"))>0,"Sí","No") -> No
B15: Pendientes por hacer | D15: =COUNTIFS(Pendientes!$C$2:$C$200,$C$4,Pendientes!$H$2:$H$200,"Por hacer") -> 0
B16: MP ejecutadas / programadas | D16: =IFERROR(VLOOKUP($C$4,'MP Carta 2026'!$A$4:$Z$969,22,FALSE())&" / "&VLOOKUP($C$4,'MP Carta 2026'!$A$4:$Z$969,21,FALSE()),"—") -> 1 / 1
B18: PREVENTIVO 2026 (por mes)
B19: Ene | C19: Feb | D19: Mar | E19: Abr | F19: May | G19: Jun
B20: =IFERROR(VLOOKUP($C$4,'MP Carta 2026'!$A$4:$T$969,9,FALSE()),"") -> 0 | C20: =IFERROR(VLOOKUP($C$4,'MP Carta 2026'!$A$4:$T$969,10,FALSE()),"") -> 0 | D20: =IFERROR(VLOOKUP($C$4,'MP Carta 2026'!$A$4:$T$969,11,FALSE()),"") -> 0 | E20: =IFERROR(VLOOKUP($C$4,'MP Carta 2026'!$A$4:$T$969,12,FALSE()),"") -> E | F20: =IFERROR(VLOOKUP($C$4,'MP Carta 2026'!$A$4:$T$969,13,FALSE()),"") -> 0 | G20: =IFERROR(VLOOKUP($C$4,'MP Carta 2026'!$A$4:$T$969,14,FALSE()),"") -> 0
B21: Jul | C21: Ago | D21: Sep | E21: Oct | F21: Nov | G21: Dic
B22: =IFERROR(VLOOKUP($C$4,'MP Carta 2026'!$A$4:$T$969,15,FALSE()),"") -> 0 | C22: =IFERROR(VLOOKUP($C$4,'MP Carta 2026'!$A$4:$T$969,16,FALSE()),"") -> 0 | D22: =IFERROR(VLOOKUP($C$4,'MP Carta 2026'!$A$4:$T$969,17,FALSE()),"") -> 0 | E22: =IFERROR(VLOOKUP($C$4,'MP Carta 2026'!$A$4:$T$969,18,FALSE()),"") -> 0 | F22: =IFERROR(VLOOKUP($C$4,'MP Carta 2026'!$A$4:$T$969,19,FALSE()),"") -> 0 | G22: =IFERROR(VLOOKUP($C$4,'MP Carta 2026'!$A$4:$T$969,20,FALSE()),"") -> 0
B24: HISTORIAL CORRECTIVO
B25: Folio | C25: Fecha OT | D25: Requerimiento | E25: Estado | F25: Cierre
B26: =IFERROR(INDEX('1. Órdenes de Trabajo'!$A$2:$A$301,$T26),"") | C26: =IFERROR(INDEX('1. Órdenes de Trabajo'!$B$2:$B$301,$T26),"") | D26: =IFERROR(INDEX('1. Órdenes de Trabajo'!$D$2:$D$301,$T26),"") | E26: =IFERROR(INDEX('1. Órdenes de Trabajo'!$J$2:$J$301,$T26),"") | F26: =IFERROR(INDEX('1. Órdenes de Trabajo'!$K$2:$K$301,$T26),"") | T26: =IFERROR(_xludf.AGGREGATE(15,6,(ROW('1. Órdenes de Trabajo'!$F$2:$F$301)-ROW('1. Órdenes de Trabajo'!$F$2)+1)/('1. Órdenes de Trabajo'!$F$2:$F$301=$C$4),1),"")
B27: =IFERROR(INDEX('1. Órdenes de Trabajo'!$A$2:$A$301,$T27),"") | C27: =IFERROR(INDEX('1. Órdenes de Trabajo'!$B$2:$B$301,$T27),"") | D27: =IFERROR(INDEX('1. Órdenes de Trabajo'!$D$2:$D$301,$T27),"") | E27: =IFERROR(INDEX('1. Órdenes de Trabajo'!$J$2:$J$301,$T27),"") | F27: =IFERROR(INDEX('1. Órdenes de Trabajo'!$K$2:$K$301,$T27),"") | T27: =IFERROR(_xludf.AGGREGATE(15,6,(ROW('1. Órdenes de Trabajo'!$F$2:$F$301)-ROW('1. Órdenes de Trabajo'!$F$2)+1)/('1. Órdenes de Trabajo'!$F$2:$F$301=$C$4),2),"")
B28: =IFERROR(INDEX('1. Órdenes de Trabajo'!$A$2:$A$301,$T28),"") | C28: =IFERROR(INDEX('1. Órdenes de Trabajo'!$B$2:$B$301,$T28),"") | D28: =IFERROR(INDEX('1. Órdenes de Trabajo'!$D$2:$D$301,$T28),"") | E28: =IFERROR(INDEX('1. Órdenes de Trabajo'!$J$2:$J$301,$T28),"") | F28: =IFERROR(INDEX('1. Órdenes de Trabajo'!$K$2:$K$301,$T28),"") | T28: =IFERROR(_xludf.AGGREGATE(15,6,(ROW('1. Órdenes de Trabajo'!$F$2:$F$301)-ROW('1. Órdenes de Trabajo'!$F$2)+1)/('1. Órdenes de Trabajo'!$F$2:$F$301=$C$4),3),"")
B29: =IFERROR(INDEX('1. Órdenes de Trabajo'!$A$2:$A$301,$T29),"") | C29: =IFERROR(INDEX('1. Órdenes de Trabajo'!$B$2:$B$301,$T29),"") | D29: =IFERROR(INDEX('1. Órdenes de Trabajo'!$D$2:$D$301,$T29),"") | E29: =IFERROR(INDEX('1. Órdenes de Trabajo'!$J$2:$J$301,$T29),"") | F29: =IFERROR(INDEX('1. Órdenes de Trabajo'!$K$2:$K$301,$T29),"") | T29: =IFERROR(_xludf.AGGREGATE(15,6,(ROW('1. Órdenes de Trabajo'!$F$2:$F$301)-ROW('1. Órdenes de Trabajo'!$F$2)+1)/('1. Órdenes de Trabajo'!$F$2:$F$301=$C$4),4),"")
B30: =IFERROR(INDEX('1. Órdenes de Trabajo'!$A$2:$A$301,$T30),"") | C30: =IFERROR(INDEX('1. Órdenes de Trabajo'!$B$2:$B$301,$T30),"") | D30: =IFERROR(INDEX('1. Órdenes de Trabajo'!$D$2:$D$301,$T30),"") | E30: =IFERROR(INDEX('1. Órdenes de Trabajo'!$J$2:$J$301,$T30),"") | F30: =IFERROR(INDEX('1. Órdenes de Trabajo'!$K$2:$K$301,$T30),"") | T30: =IFERROR(_xludf.AGGREGATE(15,6,(ROW('1. Órdenes de Trabajo'!$F$2:$F$301)-ROW('1. Órdenes de Trabajo'!$F$2)+1)/('1. Órdenes de Trabajo'!$F$2:$F$301=$C$4),5),"")
B31: =IFERROR(INDEX('1. Órdenes de Trabajo'!$A$2:$A$301,$T31),"") | C31: =IFERROR(INDEX('1. Órdenes de Trabajo'!$B$2:$B$301,$T31),"") | D31: =IFERROR(INDEX('1. Órdenes de Trabajo'!$D$2:$D$301,$T31),"") | E31: =IFERROR(INDEX('1. Órdenes de Trabajo'!$J$2:$J$301,$T31),"") | F31: =IFERROR(INDEX('1. Órdenes de Trabajo'!$K$2:$K$301,$T31),"") | T31: =IFERROR(_xludf.AGGREGATE(15,6,(ROW('1. Órdenes de Trabajo'!$F$2:$F$301)-ROW('1. Órdenes de Trabajo'!$F$2)+1)/('1. Órdenes de Trabajo'!$F$2:$F$301=$C$4),6),"")
B33: HISTORIAL PREVENTIVO
B34: Mes | C34: Resultado | D34: Fecha | E34: Ingeniero
B35: =IFERROR(INDEX('Registro MP'!$G$2:$G$301,$T35),"") | C35: =IFERROR(INDEX('Registro MP'!$J$2:$J$301,$T35),"") | D35: =IFERROR(INDEX('Registro MP'!$L$2:$L$301,$T35),"") | E35: =IFERROR(INDEX('Registro MP'!$N$2:$N$301,$T35),"") | T35: =IFERROR(_xludf.AGGREGATE(15,6,(ROW('Registro MP'!$A$2:$A$301)-ROW('Registro MP'!$A$2)+1)/('Registro MP'!$A$2:$A$301=$C$4),1),"")
B36: =IFERROR(INDEX('Registro MP'!$G$2:$G$301,$T36),"") | C36: =IFERROR(INDEX('Registro MP'!$J$2:$J$301,$T36),"") | D36: =IFERROR(INDEX('Registro MP'!$L$2:$L$301,$T36),"") | E36: =IFERROR(INDEX('Registro MP'!$N$2:$N$301,$T36),"") | T36: =IFERROR(_xludf.AGGREGATE(15,6,(ROW('Registro MP'!$A$2:$A$301)-ROW('Registro MP'!$A$2)+1)/('Registro MP'!$A$2:$A$301=$C$4),2),"")
B37: =IFERROR(INDEX('Registro MP'!$G$2:$G$301,$T37),"") | C37: =IFERROR(INDEX('Registro MP'!$J$2:$J$301,$T37),"") | D37: =IFERROR(INDEX('Registro MP'!$L$2:$L$301,$T37),"") | E37: =IFERROR(INDEX('Registro MP'!$N$2:$N$301,$T37),"") | T37: =IFERROR(_xludf.AGGREGATE(15,6,(ROW('Registro MP'!$A$2:$A$301)-ROW('Registro MP'!$A$2)+1)/('Registro MP'!$A$2:$A$301=$C$4),3),"")
B38: =IFERROR(INDEX('Registro MP'!$G$2:$G$301,$T38),"") | C38: =IFERROR(INDEX('Registro MP'!$J$2:$J$301,$T38),"") | D38: =IFERROR(INDEX('Registro MP'!$L$2:$L$301,$T38),"") | E38: =IFERROR(INDEX('Registro MP'!$N$2:$N$301,$T38),"") | T38: =IFERROR(_xludf.AGGREGATE(15,6,(ROW('Registro MP'!$A$2:$A$301)-ROW('Registro MP'!$A$2)+1)/('Registro MP'!$A$2:$A$301=$C$4),4),"")
B39: =IFERROR(INDEX('Registro MP'!$G$2:$G$301,$T39),"") | C39: =IFERROR(INDEX('Registro MP'!$J$2:$J$301,$T39),"") | D39: =IFERROR(INDEX('Registro MP'!$L$2:$L$301,$T39),"") | E39: =IFERROR(INDEX('Registro MP'!$N$2:$N$301,$T39),"") | T39: =IFERROR(_xludf.AGGREGATE(15,6,(ROW('Registro MP'!$A$2:$A$301)-ROW('Registro MP'!$A$2)+1)/('Registro MP'!$A$2:$A$301=$C$4),5),"")
B40: =IFERROR(INDEX('Registro MP'!$G$2:$G$301,$T40),"") | C40: =IFERROR(INDEX('Registro MP'!$J$2:$J$301,$T40),"") | D40: =IFERROR(INDEX('Registro MP'!$L$2:$L$301,$T40),"") | E40: =IFERROR(INDEX('Registro MP'!$N$2:$N$301,$T40),"") | T40: =IFERROR(_xludf.AGGREGATE(15,6,(ROW('Registro MP'!$A$2:$A$301)-ROW('Registro MP'!$A$2)+1)/('Registro MP'!$A$2:$A$301=$C$4),6),"")
B41: =IFERROR(INDEX('Registro MP'!$G$2:$G$301,$T41),"") | C41: =IFERROR(INDEX('Registro MP'!$J$2:$J$301,$T41),"") | D41: =IFERROR(INDEX('Registro MP'!$L$2:$L$301,$T41),"") | E41: =IFERROR(INDEX('Registro MP'!$N$2:$N$301,$T41),"") | T41: =IFERROR(_xludf.AGGREGATE(15,6,(ROW('Registro MP'!$A$2:$A$301)-ROW('Registro MP'!$A$2)+1)/('Registro MP'!$A$2:$A$301=$C$4),7),"")
B42: =IFERROR(INDEX('Registro MP'!$G$2:$G$301,$T42),"") | C42: =IFERROR(INDEX('Registro MP'!$J$2:$J$301,$T42),"") | D42: =IFERROR(INDEX('Registro MP'!$L$2:$L$301,$T42),"") | E42: =IFERROR(INDEX('Registro MP'!$N$2:$N$301,$T42),"") | T42: =IFERROR(_xludf.AGGREGATE(15,6,(ROW('Registro MP'!$A$2:$A$301)-ROW('Registro MP'!$A$2)+1)/('Registro MP'!$A$2:$A$301=$C$4),8),"")
B43: =IFERROR(INDEX('Registro MP'!$G$2:$G$301,$T43),"") | C43: =IFERROR(INDEX('Registro MP'!$J$2:$J$301,$T43),"") | D43: =IFERROR(INDEX('Registro MP'!$L$2:$L$301,$T43),"") | E43: =IFERROR(INDEX('Registro MP'!$N$2:$N$301,$T43),"") | T43: =IFERROR(_xludf.AGGREGATE(15,6,(ROW('Registro MP'!$A$2:$A$301)-ROW('Registro MP'!$A$2)+1)/('Registro MP'!$A$2:$A$301=$C$4),9),"")
B44: =IFERROR(INDEX('Registro MP'!$G$2:$G$301,$T44),"") | C44: =IFERROR(INDEX('Registro MP'!$J$2:$J$301,$T44),"") | D44: =IFERROR(INDEX('Registro MP'!$L$2:$L$301,$T44),"") | E44: =IFERROR(INDEX('Registro MP'!$N$2:$N$301,$T44),"") | T44: =IFERROR(_xludf.AGGREGATE(15,6,(ROW('Registro MP'!$A$2:$A$301)-ROW('Registro MP'!$A$2)+1)/('Registro MP'!$A$2:$A$301=$C$4),10),"")
B46: PENDIENTES DEL EQUIPO
B47: Tipo | C47: Estado | D47: Vence | E47: Responsable | F47: Descripción
...

Sheet Tablero
A1: Tablero
A2: Operatividad correctiva en tiempo real y avance del programa preventivo 2026 · se actualiza solo al cargar datos
A3: Hoy: | B3: =TODAY() -> 46191
A5: Casos abiertos | B5: Equipos No Operativos | C5: En Servicio Técnico | D5: Dados de baja | E5: Casos cerrados | F5: Pendientes documentales
A6: =COUNTIF('1. Órdenes de Trabajo'!$J$2:$J$301,"Abierto") -> 11 | B6: =COUNTIFS('1. Órdenes de Trabajo'!$J$2:$J$301,"Abierto",'1. Órdenes de Trabajo'!$H$2:$H$301,"No Operativo") -> 11 | C6: =SUMPRODUCT(('5. Servicio Técnico (Envíos)'!$A$2:$A$301<>"")*('5. Servicio Técnico (Envíos)'!$I$2:$I$301="")) -> 8 | D6: =COUNTIF('6. Bajas'!$A$2:$A$301,"?*") -> 0 | E6: =COUNTIF('1. Órdenes de Trabajo'!$J$2:$J$301,"Cerrado") -> 4 | F6: =COUNTIF('4. Visitas Técnicas'!$L$2:$L$301,"No")+COUNTIF('5. Servicio Técnico (Envíos)'!$M$2:$M$301,"No") -> 2
A9: Folio SIGEM | B9: Equipo | C9: Servicio | D9: Estado actual | E9: Técnico asignado | F9: Fecha OT | G9: Días abierto | H9: Evento
A10: =IF('1. Órdenes de Trabajo'!$J2="Abierto",'1. Órdenes de Trabajo'!$A2,"") | B10: =IF('1. Órdenes de Trabajo'!$J2="Abierto",'1. Órdenes de Trabajo'!$E2,"") | C10: =IF('1. Órdenes de Trabajo'!$J2="Abierto",'1. Órdenes de Trabajo'!$I2,"") | D10: =IF('1. Órdenes de Trabajo'!$J2="Abierto",IF(COUNTIF('6. Bajas'!$A$2:$A$301,'1. Órdenes de Trabajo'!$A2)>0,"Baja",IF(SUMPRODUCT(('5. Servicio Técnico (Envíos)'!$A$2:$A$301='1. Órdenes de Trabajo'!$A2)*('5. Servicio Técnico (Envíos)'!$I$2:$I$301=""))>0,"Servicio Técnico",'1. Órdenes de Trabajo'!$H2)),"") | E10: =IF('1. Órdenes de Trabajo'!$J2="Abierto",'1. Órdenes de Trabajo'!$C2,"") | F10: =IF('1. Órdenes de Trabajo'!$J2="Abierto",'1. Órdenes de Trabajo'!$B2,"") | G10: =IF('1. Órdenes de Trabajo'!$J2="Abierto",IF('1. Órdenes de Trabajo'!$B2="","",TODAY()-DATE(VALUE(MID('1. Órdenes de Trabajo'!$B2,7,4)),VALUE(MID('1. Órdenes de Trabajo'!$B2,4,2)),VALUE(MID('1. Órdenes de Trabajo'!$B2,1,2)))),"") | H10: =IF('1. Órdenes de Trabajo'!$J2="Abierto",'1. Órdenes de Trabajo'!$J2,"")
A11: =IF('1. Órdenes de Trabajo'!$J3="Abierto",'1. Órdenes de Trabajo'!$A3,"") -> 2025-121109-19-18809 | B11: =IF('1. Órdenes de Trabajo'!$J3="Abierto",'1. Órdenes de Trabajo'!$E3,"") -> Ventilador Mecánico | C11: =IF('1. Órdenes de Trabajo'!$J3="Abierto",'1. Órdenes de Trabajo'!$I3,"") -> UPC Pediátrica | D11: =IF('1. Órdenes de Trabajo'!$J3="Abierto",IF(COUNTIF('6. Bajas'!$A$2:$A$301,'1. Órdenes de Trabajo'!$A3)>0,"Baja",IF(SUMPRODUCT(('5. Servicio Técnico (Envíos)'!$A$2:$A$301='1. Órdenes de Trabajo'!$A3)*('5. Servicio Técnico (Envíos)'!$I$2:$I$301=""))>0,"Servicio Técnico",'1. Órdenes de Trabajo'!$H3)),"") -> No Operativo | E11: =IF('1. Órdenes de Trabajo'!$J3="Abierto",'1. Órdenes de Trabajo'!$C3,"") -> Ricardo Matus Aroca | F11: =IF('1. Órdenes de Trabajo'!$J3="Abierto",'1. Órdenes de Trabajo'!$B3,"") -> 24-10-2025 | G11: =IF('1. Órdenes de Trabajo'!$J3="Abierto",IF('1. Órdenes de Trabajo'!$B3="","",TODAY()-DATE(VALUE(MID('1. Órdenes de Trabajo'!$B3,7,4)),VALUE(MID('1. Órdenes de Trabajo'!$B3,4,2)),VALUE(MID('1. Órdenes de Trabajo'!$B3,1,2)))),"") -> 237 | H11: =IF('1. Órdenes de Trabajo'!$J3="Abierto",'1. Órdenes de Trabajo'!$J3,"") -> Abierto
A12: =IF('1. Órdenes de Trabajo'!$J4="Abierto",'1. Órdenes de Trabajo'!$A4,"") | B12: =IF('1. Órdenes de Trabajo'!$J4="Abierto",'1. Órdenes de Trabajo'!$E4,"") | C12: =IF('1. Órdenes de Trabajo'!$J4="Abierto",'1. Órdenes de Trabajo'!$I4,"") | D12: =IF('1. Órdenes de Trabajo'!$J4="Abierto",IF(COUNTIF('6. Bajas'!$A$2:$A$301,'1. Órdenes de Trabajo'!$A4)>0,"Baja",IF(SUMPRODUCT(('5. Servicio Técnico (Envíos)'!$A$2:$A$301='1. Órdenes de Trabajo'!$A4)*('5. Servicio Técnico (Envíos)'!$I$2:$I$301=""))>0,"Servicio Técnico",'1. Órdenes de Trabajo'!$H4)),"") | E12: =IF('1. Órdenes de Trabajo'!$J4="Abierto",'1. Órdenes de Trabajo'!$C4,"") | F12: =IF('1. Órdenes de Trabajo'!$J4="Abierto",'1. Órdenes de Trabajo'!$B4,"") | G12: =IF('1. Órdenes de Trabajo'!$J4="Abierto",IF('1. Órdenes de Trabajo'!$B4="","",TODAY()-DATE(VALUE(MID('1. Órdenes de Trabajo'!$B4,7,4)),VALUE(MID('1. Órdenes de Trabajo'!$B4,4,2)),VALUE(MID('1. Órdenes de Trabajo'!$B4,1,2)))),"") | H12: =IF('1. Órdenes de Trabajo'!$J4="Abierto",'1. Órdenes de Trabajo'!$J4,"")
A13: =IF('1. Órdenes de Trabajo'!$J5="Abierto",'1. Órdenes de Trabajo'!$A5,"") | B13: =IF('1. Órdenes de Trabajo'!$J5="Abierto",'1. Órdenes de Trabajo'!$E5,"") | C13: =IF('1. Órdenes de Trabajo'!$J5="Abierto",'1. Órdenes de Trabajo'!$I5,"") | D13: =IF('1. Órdenes de Trabajo'!$J5="Abierto",IF(COUNTIF('6. Bajas'!$A$2:$A$301,'1. Órdenes de Trabajo'!$A5)>0,"Baja",IF(SUMPRODUCT(('5. Servicio Técnico (Envíos)'!$A$2:$A$301='1. Órdenes de Trabajo'!$A5)*('5. Servicio Técnico (Envíos)'!$I$2:$I$301=""))>0,"Servicio Técnico",'1. Órdenes de Trabajo'!$H5)),"") | E13: =IF('1. Órdenes de Trabajo'!$J5="Abierto",'1. Órdenes de Trabajo'!$C5,"") | F13: =IF('1. Órdenes de Trabajo'!$J5="Abierto",'1. Órdenes de Trabajo'!$B5,"") | G13: =IF('1. Órdenes de Trabajo'!$J5="Abierto",IF('1. Órdenes de Trabajo'!$B5="","",TODAY()-DATE(VALUE(MID('1. Órdenes de Trabajo'!$B5,7,4)),VALUE(MID('1. Órdenes de Trabajo'!$B5,4,2)),VALUE(MID('1. Órdenes de Trabajo'!$B5,1,2)))),"") | H13: =IF('1. Órdenes de Trabajo'!$J5="Abierto",'1. Órdenes de Trabajo'!$J5,"")
A14: =IF('1. Órdenes de Trabajo'!$J6="Abierto",'1. Órdenes de Trabajo'!$A6,"") -> 2026-121109-19-6215 | B14: =IF('1. Órdenes de Trabajo'!$J6="Abierto",'1. Órdenes de Trabajo'!$E6,"") -> Máquina Diálisis | C14: =IF('1. Órdenes de Trabajo'!$J6="Abierto",'1. Órdenes de Trabajo'!$I6,"") -> Hemodiálisis | D14: =IF('1. Órdenes de Trabajo'!$J6="Abierto",IF(COUNTIF('6. Bajas'!$A$2:$A$301,'1. Órdenes de Trabajo'!$A6)>0,"Baja",IF(SUMPRODUCT(('5. Servicio Técnico (Envíos)'!$A$2:$A$301='1. Órdenes de Trabajo'!$A6)*('5. Servicio Técnico (Envíos)'!$I$2:$I$301=""))>0,"Servicio Técnico",'1. Órdenes de Trabajo'!$H6)),"") -> No Operativo | E14: =IF('1. Órdenes de Trabajo'!$J6="Abierto",'1. Órdenes de Trabajo'!$C6,"") -> Cristián Beltrán Oviedo | F14: =IF('1. Órdenes de Trabajo'!$J6="Abierto",'1. Órdenes de Trabajo'!$B6,"") -> 06-04-2026 | G14: =IF('1. Órdenes de Trabajo'!$J6="Abierto",IF('1. Órdenes de Trabajo'!$B6="","",TODAY()-DATE(VALUE(MID('1. Órdenes de Trabajo'!$B6,7,4)),VALUE(MID('1. Órdenes de Trabajo'!$B6,4,2)),VALUE(MID('1. Órdenes de Trabajo'!$B6,1,2)))),"") -> 73 | H14: =IF('1. Órdenes de Trabajo'!$J6="Abierto",'1. Órdenes de Trabajo'!$J6,"") -> Abierto
A15: =IF('1. Órdenes de Trabajo'!$J7="Abierto",'1. Órdenes de Trabajo'!$A7,"") -> 2026-121109-19-6271 | B15: =IF('1. Órdenes de Trabajo'!$J7="Abierto",'1. Órdenes de Trabajo'!$E7,"") -> Ventilador Mecánico | C15: =IF('1. Órdenes de Trabajo'!$J7="Abierto",'1. Órdenes de Trabajo'!$I7,"") -> UPC 3er Piso | D15: =IF('1. Órdenes de Trabajo'!$J7="Abierto",IF(COUNTIF('6. Bajas'!$A$2:$A$301,'1. Órdenes de Trabajo'!$A7)>0,"Baja",IF(SUMPRODUCT(('5. Servicio Técnico (Envíos)'!$A$2:$A$301='1. Órdenes de Trabajo'!$A7)*('5. Servicio Técnico (Envíos)'!$I$2:$I$301=""))>0,"Servicio Técnico",'1. Órdenes de Trabajo'!$H7)),"") -> Servicio Técnico | E15: =IF('1. Órdenes de Trabajo'!$J7="Abierto",'1. Órdenes de Trabajo'!$C7,"") -> Ricardo Matus Aroca | F15: =IF('1. Órdenes de Trabajo'!$J7="Abierto",'1. Órdenes de Trabajo'!$B7,"") -> 07-04-2026 | G15: =IF('1. Órdenes de Trabajo'!$J7="Abierto",IF('1. Órdenes de Trabajo'!$B7="","",TODAY()-DATE(VALUE(MID('1. Órdenes de Trabajo'!$B7,7,4)),VALUE(MID('1. Órdenes de Trabajo'!$B7,4,2)),VALUE(MID('1. Órdenes de Trabajo'!$B7,1,2)))),"") -> 72 | H15: =IF('1. Órdenes de Trabajo'!$J7="Abierto",'1. Órdenes de Trabajo'!$J7,"") -> Abierto
A16: =IF('1. Órdenes de Trabajo'!$J8="Abierto",'1. Órdenes de Trabajo'!$A8,"") -> 2026-121109-19-6374 | B16: =IF('1. Órdenes de Trabajo'!$J8="Abierto",'1. Órdenes de Trabajo'!$E8,"") -> Ventilador Mecánico | C16: =IF('1. Órdenes de Trabajo'!$J8="Abierto",'1. Órdenes de Trabajo'!$I8,"") -> UPC 3er Piso | D16: =IF('1. Órdenes de Trabajo'!$J8="Abierto",IF(COUNTIF('6. Bajas'!$A$2:$A$301,'1. Órdenes de Trabajo'!$A8)>0,"Baja",IF(SUMPRODUCT(('5. Servicio Técnico (Envíos)'!$A$2:$A$301='1. Órdenes de Trabajo'!$A8)*('5. Servicio Técnico (Envíos)'!$I$2:$I$301=""))>0,"Servicio Técnico",'1. Órdenes de Trabajo'!$H8)),"") -> Servicio Técnico | E16: =IF('1. Órdenes de Trabajo'!$J8="Abierto",'1. Órdenes de Trabajo'!$C8,"") -> Ricardo Matus Aroca | F16: =IF('1. Órdenes de Trabajo'!$J8="Abierto",'1. Órdenes de Trabajo'!$B8,"") -> 08-04-2026 | G16: =IF('1. Órdenes de Trabajo'!$J8="Abierto",IF('1. Órdenes de Trabajo'!$B8="","",TODAY()-DATE(VALUE(MID('1. Órdenes de Trabajo'!$B8,7,4)),VALUE(MID('1. Órdenes de Trabajo'!$B8,4,2)),VALUE(MID('1. Órdenes de Trabajo'!$B8,1,2)))),"") -> 71 | H16: =IF('1. Órdenes de Trabajo'!$J8="Abierto",'1. Órdenes de Trabajo'!$J8,"") -> Abierto
A17: =IF('1. Órdenes de Trabajo'!$J9="Abierto",'1. Órdenes de Trabajo'!$A9,"") | B17: =IF('1. Órdenes de Trabajo'!$J9="Abierto",'1. Órdenes de Trabajo'!$E9,"") | C17: =IF('1. Órdenes de Trabajo'!$J9="Abierto",'1. Órdenes de Trabajo'!$I9,"") | D17: =IF('1. Órdenes de Trabajo'!$J9="Abierto",IF(COUNTIF('6. Bajas'!$A$2:$A$301,'1. Órdenes de Trabajo'!$A9)>0,"Baja",IF(SUMPRODUCT(('5. Servicio Técnico (Envíos)'!$A$2:$A$301='1. Órdenes de Trabajo'!$A9)*('5. Servicio Técnico (Envíos)'!$I$2:$I$301=""))>0,"Servicio Técnico",'1. Órdenes de Trabajo'!$H9)),"") | E17: =IF('1. Órdenes de Trabajo'!$J9="Abierto",'1. Órdenes de Trabajo'!$C9,"") | F17: =IF('1. Órdenes de Trabajo'!$J9="Abierto",'1. Órdenes de Trabajo'!$B9,"") | G17: =IF('1. Órdenes de Trabajo'!$J9="Abierto",IF('1. Órdenes de Trabajo'!$B9="","",TODAY()-DATE(VALUE(MID('1. Órdenes de Trabajo'!$B9,7,4)),VALUE(MID('1. Órdenes de Trabajo'!$B9,4,2)),VALUE(MID('1. Órdenes de Trabajo'!$B9,1,2)))),"") | H17: =IF('1. Órdenes de Trabajo'!$J9="Abierto",'1. Órdenes de Trabajo'!$J9,"")
A18: =IF('1. Órdenes de Trabajo'!$J10="Abierto",'1. Órdenes de Trabajo'!$A10,"") -> 2026-121109-19-7762 | B18: =IF('1. Órdenes de Trabajo'!$J10="Abierto",'1. Órdenes de Trabajo'!$E10,"") -> Monitor Multiparámetros | C18: =IF('1. Órdenes de Trabajo'!$J10="Abierto",'1. Órdenes de Trabajo'!$I10,"") -> Medicina | D18: =IF('1. Órdenes de Trabajo'!$J10="Abierto",IF(COUNTIF('6. Bajas'!$A$2:$A$301,'1. Órdenes de Trabajo'!$A10)>0,"Baja",IF(SUMPRODUCT(('5. Servicio Técnico (Envíos)'!$A$2:$A$301='1. Órdenes de Trabajo'!$A10)*('5. Servicio Técnico (Envíos)'!$I$2:$I$301=""))>0,"Servicio Técnico",'1. Órdenes de Trabajo'!$H10)),"") -> Servicio Técnico | E18: =IF('1. Órdenes de Trabajo'!$J10="Abierto",'1. Órdenes de Trabajo'!$C10,"") -> Carlos Bahamondes Seguel | F18: =IF('1. Órdenes de Trabajo'!$J10="Abierto",'1. Órdenes de Trabajo'!$B10,"") -> 27-04-2026 | G18: =IF('1. Órdenes de Trabajo'!$J10="Abierto",IF('1. Órdenes de Trabajo'!$B10="","",TODAY()-DATE(VALUE(MID('1. Órdenes de Trabajo'!$B10,7,4)),VALUE(MID('1. Órdenes de Trabajo'!$B10,4,2)),VALUE(MID('1. Órdenes de Trabajo'!$B10,1,2)))),"") -> 52 | H18: =IF('1. Órdenes de Trabajo'!$J10="Abierto",'1. Órdenes de Trabajo'!$J10,"") -> Abierto
A19: =IF('1. Órdenes de Trabajo'!$J11="Abierto",'1. Órdenes de Trabajo'!$A11,"") -> 2026-121109-19-9046 | B19: =IF('1. Órdenes de Trabajo'!$J11="Abierto",'1. Órdenes de Trabajo'!$E11,"") -> Monitor Multiparámetros | C19: =IF('1. Órdenes de Trabajo'!$J11="Abierto",'1. Órdenes de Trabajo'!$I11,"") -> Medicina | D19: =IF('1. Órdenes de Trabajo'!$J11="Abierto",IF(COUNTIF('6. Bajas'!$A$2:$A$301,'1. Órdenes de Trabajo'!$A11)>0,"Baja",IF(SUMPRODUCT(('5. Servicio Técnico (Envíos)'!$A$2:$A$301='1. Órdenes de Trabajo'!$A11)*('5. Servicio Técnico (Envíos)'!$I$2:$I$301=""))>0,"Servicio Técnico",'1. Órdenes de Trabajo'!$H11)),"") -> Servicio Técnico | E19: =IF('1. Órdenes de Trabajo'!$J11="Abierto",'1. Órdenes de Trabajo'!$C11,"") -> Carlos Bahamondes Seguel | F19: =IF('1. Órdenes de Trabajo'!$J11="Abierto",'1. Órdenes de Trabajo'!$B11,"") -> 14-05-2026 | G19: =IF('1. Órdenes de Trabajo'!$J11="Abierto",IF('1. Órdenes de Trabajo'!$B11="","",TODAY()-DATE(VALUE(MID('1. Órdenes de Trabajo'!$B11,7,4)),VALUE(MID('1. Órdenes de Trabajo'!$B11,4,2)),VALUE(MID('1. Órdenes de Trabajo'!$B11,1,2)))),"") -> 35 | H19: =IF('1. Órdenes de Trabajo'!$J11="Abierto",'1. Órdenes de Trabajo'!$J11,"") -> Abierto
A20: =IF('1. Órdenes de Trabajo'!$J12="Abierto",'1. Órdenes de Trabajo'!$A12,"") -> 2026-121109-19-9887 | B20: =IF('1. Órdenes de Trabajo'!$J12="Abierto",'1. Órdenes de Trabajo'!$E12,"") -> Monitor Multiparámetros | C20: =IF('1. Órdenes de Trabajo'!$J12="Abierto",'1. Órdenes de Trabajo'!$I12,"") -> Pabellones Gineco-Obstétricos | D20: =IF('1. Órdenes de Trabajo'!$J12="Abierto",IF(COUNTIF('6. Bajas'!$A$2:$A$301,'1. Órdenes de Trabajo'!$A12)>0,"Baja",IF(SUMPRODUCT(('5. Servicio Técnico (Envíos)'!$A$2:$A$301='1. Órdenes de Trabajo'!$A12)*('5. Servicio Técnico (Envíos)'!$I$2:$I$301=""))>0,"Servicio Técnico",'1. Órdenes de Trabajo'!$H12)),"") -> Servicio Técnico | E20: =IF('1. Órdenes de Trabajo'!$J12="Abierto",'1. Órdenes de Trabajo'!$C12,"") -> Cristina Rozas Urrutia | F20: =IF('1. Órdenes de Trabajo'!$J12="Abierto",'1. Órdenes de Trabajo'!$B12,"") -> 28-05-2026 | G20: =IF('1. Órdenes de Trabajo'!$J12="Abierto",IF('1. Órdenes de Trabajo'!$B12="","",TODAY()-DATE(VALUE(MID('1. Órdenes de Trabajo'!$B12,7,4)),VALUE(MID('1. Órdenes de Trabajo'!$B12,4,2)),VALUE(MID('1. Órdenes de Trabajo'!$B12,1,2)))),"") -> 21 | H20: =IF('1. Órdenes de Trabajo'!$J12="Abierto",'1. Órdenes de Trabajo'!$J12,"") -> Abierto
A21: =IF('1. Órdenes de Trabajo'!$J13="Abierto",'1. Órdenes de Trabajo'!$A13,"") -> 2026-121109-19-10081 | B21: =IF('1. Órdenes de Trabajo'!$J13="Abierto",'1. Órdenes de Trabajo'!$E13,"") -> Máquina Diálisis | C21: =IF('1. Órdenes de Trabajo'!$J13="Abierto",'1. Órdenes de Trabajo'!$I13,"") -> UPC Adulto | D21: =IF('1. Órdenes de Trabajo'!$J13="Abierto",IF(COUNTIF('6. Bajas'!$A$2:$A$301,'1. Órdenes de Trabajo'!$A13)>0,"Baja",IF(SUMPRODUCT(('5. Servicio Técnico (Envíos)'!$A$2:$A$301='1. Órdenes de Trabajo'!$A13)*('5. Servicio Técnico (Envíos)'!$I$2:$I$301=""))>0,"Servicio Técnico",'1. Órdenes de Trabajo'!$H13)),"") -> No Operativo | E21: =IF('1. Órdenes de Trabajo'!$J13="Abierto",'1. Órdenes de Trabajo'!$C13,"") -> Cristián Beltrán Oviedo | F21: =IF('1. Órdenes de Trabajo'!$J13="Abierto",'1. Órdenes de Trabajo'!$B13,"") -> 01-06-2026 | G21: =IF('1. Órdenes de Trabajo'!$J13="Abierto",IF('1. Órdenes de Trabajo'!$B13="","",TODAY()-DATE(VALUE(MID('1. Órdenes de Trabajo'!$B13,7,4)),VALUE(MID('1. Órdenes de Trabajo'!$B13,4,2)),VALUE(MID('1. Órdenes de Trabajo'!$B13,1,2)))),"") -> 17 | H21: =IF('1. Órdenes de Trabajo'!$J13="Abierto",'1. Órdenes de Trabajo'!$J13,"") -> Abierto
... A89: =IF('1. Órdenes de Trabajo'!$J81="Abierto",'1. Órdenes de Trabajo'!$A81,"") | B89: =IF('1. Órdenes de Trabajo'!$J81="Abierto",'1. Órdenes de Trabajo'!$E81,"") | C89: =IF('1. Órdenes de Trabajo'!$J81="Abierto",'1. Órdenes de Trabajo'!$I81,"") | D89: =IF('1. Órdenes de Trabajo'!$J81="Abierto",IF(COUNTIF('6. Bajas'!$A$2:$A$301,'1. Órdenes de Trabajo'!$A81)>0,"Baja",IF(SUMPRODUCT(('5. Servicio Técnico (Envíos)'!$A$2:$A$301='1. Órdenes de Trabajo'!$A81)*('5. Servicio Técnico (Envíos)'!$I$2:$I$301=""))>0,"Servicio Técnico",'1. Órdenes de Trabajo'!$H81)),"") | E89: =IF('1. Órdenes de Trabajo'!$J81="Abierto",'1. Órdenes de Trabajo'!$C81,"") | F89: =IF('1. Órdenes de Trabajo'!$J81="Abierto",'1. Órdenes de Trabajo'!$B81,"") | G89: =IF('1. Órdenes de Trabajo'!$J81="Abierto",IF('1. Órdenes de Trabajo'!$B81="","",TODAY()-DATE(VALUE(MID('1. Órdenes de Trabajo'!$B81,7,4)),VALUE(MID('1. Órdenes de Trabajo'!$B81,4,2)),VALUE(MID('1. Órdenes de Trabajo'!$B81,1,2)))),"") | H89: =IF('1. Órdenes de Trabajo'!$J81="Abierto",'1. Órdenes de Trabajo'!$J81,"")
A91: Nota: el «Estado actual» se calcula así — si el equipo está en Bajas muestra «Baja»; si tiene un envío a servicio técnico sin retorno registrado muestra «Servicio Técnico»; en otro caso, el estado inicial de la OT. Solo se listan casos con evento «Abierto». Los días en rojo superan los 30.
A93: Pendientes documentales (equipo retornado/atendido, falta Reporte de Servicio)
A94: Incluye casos aunque la OT esté cerrada: el equipo opera, pero falta el respaldo documental para la carpeta física.
A95: Folio SIGEM | B95: Equipo | C95: Origen | D95: Empresa | E95: Resp. conseguir reporte | F95: Resp. administrativo | G95: Estado OT
A96: =IF('5. Servicio Técnico (Envíos)'!$M2="No",'5. Servicio Técnico (Envíos)'!$A2,"") -> 2025-121109-19-10024 | B96: =IF('5. Servicio Técnico (Envíos)'!$M2="No",IFERROR(VLOOKUP('5. Servicio Técnico (Envíos)'!$A2,'1. Órdenes de Trabajo'!$A$2:$E$301,5,FALSE()),""),"") -> Ventilador Mecánico | C96: =IF('5. Servicio Técnico (Envíos)'!$M2="No","Servicio técnico","") -> Servicio técnico | D96: =IF('5. Servicio Técnico (Envíos)'!$M2="No",'5. Servicio Técnico (Envíos)'!$E2,"") -> DRAGER CHILE LIMITADA | E96: =IF('5. Servicio Técnico (Envíos)'!$M2="No",'5. Servicio Técnico (Envíos)'!$N2,"") -> Ricardo Matus Aroca | F96: =IF('5. Servicio Técnico (Envíos)'!$M2="No",'5. Servicio Técnico (Envíos)'!$O2,"") -> Cristián Beltrán Oviedo | G96: =IF('5. Servicio Técnico (Envíos)'!$M2="No",IFERROR(VLOOKUP('5. Servicio Técnico (Envíos)'!$A2,'1. Órdenes de Trabajo'!$A$2:$J$301,10,FALSE()),""),"") -> Cerrado
A97: =IF('5. Servicio Técnico (Envíos)'!$M3="No",'5. Servicio Técnico (Envíos)'!$A3,"") | B97: =IF('5. Servicio Técnico (Envíos)'!$M3="No",IFERROR(VLOOKUP('5. Servicio Técnico (Envíos)'!$A3,'1. Órdenes de Trabajo'!$A$2:$E$301,5,FALSE()),""),"") | C97: =IF('5. Servicio Técnico (Envíos)'!$M3="No","Servicio técnico","") | D97: =IF('5. Servicio Técnico (Envíos)'!$M3="No",'5. Servicio Técnico (Envíos)'!$E3,"") | E97: =IF('5. Servicio Técnico (Envíos)'!$M3="No",'5. Servicio Técnico (Envíos)'!$N3,"") | F97: =IF('5. Servicio Técnico (Envíos)'!$M3="No",'5. Servicio Técnico (Envíos)'!$O3,"") | G97: =IF('5. Servicio Técnico (Envíos)'!$M3="No",IFERROR(VLOOKUP('5. Servicio Técnico (Envíos)'!$A3,'1. Órdenes de Trabajo'!$A$2:$J$301,10,FALSE()),""),"")
A98: =IF('5. Servicio Técnico (Envíos)'!$M4="No",'5. Servicio Técnico (Envíos)'!$A4,"") | B98: =IF('5. Servicio Técnico (Envíos)'!$M4="No",IFERROR(VLOOKUP('5. Servicio Técnico (Envíos)'!$A4,'1. Órdenes de Trabajo'!$A$2:$E$301,5,FALSE()),""),"") | C98: =IF('5. Servicio Técnico (Envíos)'!$M4="No","Servicio técnico","") | D98: =IF('5. Servicio Técnico (Envíos)'!$M4="No",'5. Servicio Técnico (Envíos)'!$E4,"") | E98: =IF('5. Servicio Técnico (Envíos)'!$M4="No",'5. Servicio Técnico (Envíos)'!$N4,"") | F98: =IF('5. Servicio Técnico (Envíos)'!$M4="No",'5. Servicio Técnico (Envíos)'!$O4,"") | G98: =IF('5. Servicio Técnico (Envíos)'!$M4="No",IFERROR(VLOOKUP('5. Servicio Técnico (Envíos)'!$A4,'1. Órdenes de Trabajo'!$A$2:$J$301,10,FALSE()),""),"")
A99: =IF('5. Servicio Técnico (Envíos)'!$M5="No",'5. Servicio Técnico (Envíos)'!$A5,"") | B99: =IF('5. Servicio Técnico (Envíos)'!$M5="No",IFERROR(VLOOKUP('5. Servicio Técnico (Envíos)'!$A5,'1. Órdenes de Trabajo'!$A$2:$E$301,5,FALSE()),""),"") | C99: =IF('5. Servicio Técnico (Envíos)'!$M5="No","Servicio técnico","") | D99: =IF('5. Servicio Técnico (Envíos)'!$M5="No",'5. Servicio Técnico (Envíos)'!$E5,"") | E99: =IF('5. Servicio Técnico (Envíos)'!$M5="No",'5. Servicio Técnico (Envíos)'!$N5,"") | F99: =IF('5. Servicio Técnico (Envíos)'!$M5="No",'5. Servicio Técnico (Envíos)'!$O5,"") | G99: =IF('5. Servicio Técnico (Envíos)'!$M5="No",IFERROR(VLOOKUP('5. Servicio Técnico (Envíos)'!$A5,'1. Órdenes de Trabajo'!$A$2:$J$301,10,FALSE()),""),"")
A100: =IF('5. Servicio Técnico (Envíos)'!$M6="No",'5. Servicio Técnico (Envíos)'!$A6,"") | B100: =IF('5. Servicio Técnico (Envíos)'!$M6="No",IFERROR(VLOOKUP('5. Servicio Técnico (Envíos)'!$A6,'1. Órdenes de Trabajo'!$A$2:$E$301,5,FALSE()),""),"") | C100: =IF('5. Servicio Técnico (Envíos)'!$M6="No","Servicio técnico","") | D100: =IF('5. Servicio Técnico (Envíos)'!$M6="No",'5. Servicio Técnico (Envíos)'!$E6,"") | E100: =IF('5. Servicio Técnico (Envíos)'!$M6="No",'5. Servicio Técnico (Envíos)'!$N6,"") | F100: =IF('5. Servicio Técnico (Envíos)'!$M6="No",'5. Servicio Técnico (Envíos)'!$O6,"") | G100: =IF('5. Servicio Técnico (Envíos)'!$M6="No",IFERROR(VLOOKUP('5. Servicio Técnico (Envíos)'!$A6,'1. Órdenes de Trabajo'!$A$2:$J$301,10,FALSE()),""),"")
A101: =IF('5. Servicio Técnico (Envíos)'!$M7="No",'5. Servicio Técnico (Envíos)'!$A7,"") | B101: =IF('5. Servicio Técnico (Envíos)'!$M7="No",IFERROR(VLOOKUP('5. Servicio Técnico (Envíos)'!$A7,'1. Órdenes de Trabajo'!$A$2:$E$301,5,FALSE()),""),"") | C101: =IF('5. Servicio Técnico (Envíos)'!$M7="No","Servicio técnico","") | D101: =IF('5. Servicio Técnico (Envíos)'!$M7="No",'5. Servicio Técnico (Envíos)'!$E7,"") | E101: =IF('5. Servicio Técnico (Envíos)'!$M7="No",'5. Servicio Técnico (Envíos)'!$N7,"") | F101: =IF('5. Servicio Técnico (Envíos)'!$M7="No",'5. Servicio Técnico (Envíos)'!$O7,"") | G101: =IF('5. Servicio Técnico (Envíos)'!$M7="No",IFERROR(VLOOKUP('5. Servicio Técnico (Envíos)'!$A7,'1. Órdenes de Trabajo'!$A$2:$J$301,10,FALSE()),""),"")
A102: =IF('5. Servicio Técnico (Envíos)'!$M8="No",'5. Servicio Técnico (Envíos)'!$A8,"") | B102: =IF('5. Servicio Técnico (Envíos)'!$M8="No",IFERROR(VLOOKUP('5. Servicio Técnico (Envíos)'!$A8,'1. Órdenes de Trabajo'!$A$2:$E$301,5,FALSE()),""),"") | C102: =IF('5. Servicio Técnico (Envíos)'!$M8="No","Servicio técnico","") | D102: =IF('5. Servicio Técnico (Envíos)'!$M8="No",'5. Servicio Técnico (Envíos)'!$E8,"") | E102: =IF('5. Servicio Técnico (Envíos)'!$M8="No",'5. Servicio Técnico (Envíos)'!$N8,"") | F102: =IF('5. Servicio Técnico (Envíos)'!$M8="No",'5. Servicio Técnico (Envíos)'!$O8,"") | G102: =IF('5. Servicio Técnico (Envíos)'!$M8="No",IFERROR(VLOOKUP('5. Servicio Técnico (Envíos)'!$A8,'1. Órdenes de Trabajo'!$A$2:$J$301,10,FALSE()),""),"")
A103: =IF('5. Servicio Técnico (Envíos)'!$M9="No",'5. Servicio Técnico (Envíos)'!$A9,"") | B103: =IF('5. Servicio Técnico (Envíos)'!$M9="No",IFERROR(VLOOKUP('5. Servicio Técnico (Envíos)'!$A9,'1. Órdenes de Trabajo'!$A$2:$E$301,5,FALSE()),""),"") | C103: =IF('5. Servicio Técnico (Envíos)'!$M9="No","Servicio técnico","") | D103: =IF('5. Servicio Técnico (Envíos)'!$M9="No",'5. Servicio Técnico (Envíos)'!$E9,"") | E103: =IF('5. Servicio Técnico (Envíos)'!$M9="No",'5. Servicio Técnico (Envíos)'!$N9,"") | F103: =IF('5. Servicio Técnico (Envíos)'!$M9="No",'5. Servicio Técnico (Envíos)'!$O9,"") | G103: =IF('5. Servicio Técnico (Envíos)'!$M9="No",IFERROR(VLOOKUP('5. Servicio Técnico (Envíos)'!$A9,'1. Órdenes de Trabajo'!$A$2:$J$301,10,FALSE()),""),"")
A104: =IF('5. Servicio Técnico (Envíos)'!$M10="No",'5. Servicio Técnico (Envíos)'!$A10,"") | B104: =IF('5. Servicio Técnico (Envíos)'!$M10="No",IFERROR(VLOOKUP('5. Servicio Técnico (Envíos)'!$A10,'1. Órdenes de Trabajo'!$A$2:$E$301,5,FALSE()),""),"") | C104: =IF('5. Servicio Técnico (Envíos)'!$M10="No","Servicio técnico","") | D104: =IF('5. Servicio Técnico (Envíos)'!$M10="No",'5. Servicio Técnico (Envíos)'!$E10,"") | E104: =IF('5. Servicio Técnico (Envíos)'!$M10="No",'5. Servicio Técnico (Envíos)'!$N10,"") | F104: =IF('5. Servicio Técnico (Envíos)'!$M10="No",'5. Servicio Técnico (Envíos)'!$O10,"") | G104: =IF('5. Servicio Técnico (Envíos)'!$M10="No",IFERROR(VLOOKUP('5. Servicio Técnico (Envíos)'!$A10,'1. Órdenes de Trabajo'!$A$2:$J$301,10,FALSE()),""),"")
A105: =IF('5. Servicio Técnico (Envíos)'!$M11="No",'5. Servicio Técnico (Envíos)'!$A11,"") | B105: =IF('5. Servicio Técnico (Envíos)'!$M11="No",IFERROR(VLOOKUP('5. Servicio Técnico (Envíos)'!$A11,'1. Órdenes de Trabajo'!$A$2:$E$301,5,FALSE()),""),"") | C105: =IF('5. Servicio Técnico (Envíos)'!$M11="No","Servicio técnico","") | D105: =IF('5. Servicio Técnico (Envíos)'!$M11="No",'5. Servicio Técnico (Envíos)'!$E11,"") | E105: =IF('5. Servicio Técnico (Envíos)'!$M11="No",'5. Servicio Técnico (Envíos)'!$N11,"") | F105: =IF('5. Servicio Técnico (Envíos)'!$M11="No",'5. Servicio Técnico (Envíos)'!$O11,"") | G105: =IF('5. Servicio Técnico (Envíos)'!$M11="No",IFERROR(VLOOKUP('5. Servicio Técnico (Envíos)'!$A11,'1. Órdenes de Trabajo'!$A$2:$J$301,10,FALSE()),""),"")
A106: =IF('5. Servicio Técnico (Envíos)'!$M12="No",'5. Servicio Técnico (Envíos)'!$A12,"") | B106: =IF('5. Servicio Técnico (Envíos)'!$M12="No",IFERROR(VLOOKUP('5. Servicio Técnico (Envíos)'!$A12,'1. Órdenes de Trabajo'!$A$2:$E$301,5,FALSE()),""),"") | C106: =IF('5. Servicio Técnico (Envíos)'!$M12="No","Servicio técnico","") | D106: =IF('5. Servicio Técnico (Envíos)'!$M12="No",'5. Servicio Técnico (Envíos)'!$E12,"") | E106: =IF('5. Servicio Técnico (Envíos)'!$M12="No",'5. Servicio Técnico (Envíos)'!$N12,"") | F106: =IF('5. Servicio Técnico (Envíos)'!$M12="No",'5. Servicio Técnico (Envíos)'!$O12,"") | G106: =IF('5. Servicio Técnico (Envíos)'!$M12="No",IFERROR(VLOOKUP('5. Servicio Técnico (Envíos)'!$A12,'1. Órdenes de Trabajo'!$A$2:$J$301,10,FALSE()),""),"")
A107: =IF('5. Servicio Técnico (Envíos)'!$M13="No",'5. Servicio Técnico (Envíos)'!$A13,"") | B107: =IF('5. Servicio Técnico (Envíos)'!$M13="No",IFERROR(VLOOKUP('5. Servicio Técnico (Envíos)'!$A13,'1. Órdenes de Trabajo'!$A$2:$E$301,5,FALSE()),""),"") | C107: =IF('5. Servicio Técnico (Envíos)'!$M13="No","Servicio técnico","") | D107: =IF('5. Servicio Técnico (Envíos)'!$M13="No",'5. Servicio Técnico (Envíos)'!$E13,"") | E107: =IF('5. Servicio Técnico (Envíos)'!$M13="No",'5. Servicio Técnico (Envíos)'!$N13,"") | F107: =IF('5. Servicio Técnico (Envíos)'!$M13="No",'5. Servicio Técnico (Envíos)'!$O13,"") | G107: =IF('5. Servicio Técnico (Envíos)'!$M13="No",IFERROR(VLOOKUP('5. Servicio Técnico (Envíos)'!$A13,'1. Órdenes de Trabajo'!$A$2:$J$301,10,FALSE()),""),"")
... A135: =IF('5. Servicio Técnico (Envíos)'!$M41="No",'5. Servicio Técnico (Envíos)'!$A41,"") | B135: =IF('5. Servicio Técnico (Envíos)'!$M41="No",IFERROR(VLOOKUP('5. Servicio Técnico (Envíos)'!$A41,'1. Órdenes de Trabajo'!$A$2:$E$301,5,FALSE()),""),"") | C135: =IF('5. Servicio Técnico (Envíos)'!$M41="No","Servicio técnico","") | D135: =IF('5. Servicio Técnico (Envíos)'!$M41="No",'5. Servicio Técnico (Envíos)'!$E41,"") | E135: =IF('5. Servicio Técnico (Envíos)'!$M41="No",'5. Servicio Técnico (Envíos)'!$N41,"") | F135: =IF('5. Servicio Técnico (Envíos)'!$M41="No",'5. Servicio Técnico (Envíos)'!$O41,"") | G135: =IF('5. Servicio Técnico (Envíos)'!$M41="No",IFERROR(VLOOKUP('5. Servicio Técnico (Envíos)'!$A41,'1. Órdenes de Trabajo'!$A$2:$J$301,10,FALSE()),""),"")
A136: =IF('4. Visitas Técnicas'!$L2="No",'4. Visitas Técnicas'!$A2,"") -> 2025-121109-19-10024 | B136: =IF('4. Visitas Técnicas'!$L2="No",IFERROR(VLOOKUP('4. Visitas Técnicas'!$A2,'1. Órdenes de Trabajo'!$A$2:$E$301,5,FALSE()),""),"") -> Ventilador Mecánico | C136: =IF('4. Visitas Técnicas'!$L2="No","Visita técnica","") -> Visita técnica | D136: =IF('4. Visitas Técnicas'!$L2="No",'4. Visitas Técnicas'!$C2,"") -> DRAGER CHILE LIMITADA | E136: =IF('4. Visitas Técnicas'!$L2="No",'4. Visitas Técnicas'!$M2,"") -> Ricardo Matus Aroca | F136: =IF('4. Visitas Técnicas'!$L2="No",'4. Visitas Técnicas'!$N2,"") -> Cristián Beltrán Oviedo | G136: =IF('4. Visitas Técnicas'!$L2="No",IFERROR(VLOOKUP('4. Visitas Técnicas'!$A2,'1. Órdenes de Trabajo'!$A$2:$J$301,10,FALSE()),""),"") -> Cerrado
A137: =IF('4. Visitas Técnicas'!$L3="No",'4. Visitas Técnicas'!$A3,"") | B137: =IF('4. Visitas Técnicas'!$L3="No",IFERROR(VLOOKUP('4. Visitas Técnicas'!$A3,'1. Órdenes de Trabajo'!$A$2:$E$301,5,FALSE()),""),"") | C137: =IF('4. Visitas Técnicas'!$L3="No","Visita técnica","") | D137: =IF('4. Visitas Técnicas'!$L3="No",'4. Visitas Técnicas'!$C3,"") | E137: =IF('4. Visitas Técnicas'!$L3="No",'4. Visitas Técnicas'!$M3,"") | F137: =IF('4. Visitas Técnicas'!$L3="No",'4. Visitas Técnicas'!$N3,"") | G137: =IF('4. Visitas Técnicas'!$L3="No",IFERROR(VLOOKUP('4. Visitas Técnicas'!$A3,'1. Órdenes de Trabajo'!$A$2:$J$301,10,FALSE()),""),"")
A138: =IF('4. Visitas Técnicas'!$L4="No",'4. Visitas Técnicas'!$A4,"") | B138: =IF('4. Visitas Técnicas'!$L4="No",IFERROR(VLOOKUP('4. Visitas Técnicas'!$A4,'1. Órdenes de Trabajo'!$A$2:$E$301,5,FALSE()),""),"") | C138: =IF('4. Visitas Técnicas'!$L4="No","Visita técnica","") | D138: =IF('4. Visitas Técnicas'!$L4="No",'4. Visitas Técnicas'!$C4,"") | E138: =IF('4. Visitas Técnicas'!$L4="No",'4. Visitas Técnicas'!$M4,"") | F138: =IF('4. Visitas Técnicas'!$L4="No",'4. Visitas Técnicas'!$N4,"") | G138: =IF('4. Visitas Técnicas'!$L4="No",IFERROR(VLOOKUP('4. Visitas Técnicas'!$A4,'1. Órdenes de Trabajo'!$A$2:$J$301,10,FALSE()),""),"")
A139: =IF('4. Visitas Técnicas'!$L5="No",'4. Visitas Técnicas'!$A5,"") | B139: =IF('4. Visitas Técnicas'!$L5="No",IFERROR(VLOOKUP('4. Visitas Técnicas'!$A5,'1. Órdenes de Trabajo'!$A$2:$E$301,5,FALSE()),""),"") | C139: =IF('4. Visitas Técnicas'!$L5="No","Visita técnica","") | D139: =IF('4. Visitas Técnicas'!$L5="No",'4. Visitas Técnicas'!$C5,"") | E139: =IF('4. Visitas Técnicas'!$L5="No",'4. Visitas Técnicas'!$M5,"") | F139: =IF('4. Visitas Técnicas'!$L5="No",'4. Visitas Técnicas'!$N5,"") | G139: =IF('4. Visitas Técnicas'!$L5="No",IFERROR(VLOOKUP('4. Visitas Técnicas'!$A5,'1. Órdenes de Trabajo'!$A$2:$J$301,10,FALSE()),""),"")
...

Sheet MP Carta 2026
A1: Programa de Mantención Preventiva 2026 — Carta de ejecución
A2: Un equipo por fila (los 966 de la base). Marca el código del mes en cada celda: X programada · E ejecutada · C2/C3 no ejecutada por falla · R reprogramada · B baja. La identidad del equipo se hereda de la hoja Equipos.
